Workbook

Sheet 物料清单
A1: 成品件号 | B1: K3代码 | C1: 父项产品编号 | D1: 父项产品名称 | E1: 父项产品规格 | F1: 父项单位 | G1: 子项产品编号 | H1: 子项产品名称 | I1: 子项产品规格 | J1: 子项单位 | K1: 单位用量 | L1: 备注
A2: ALZWJ43029 | B2: =VLOOKUP(A2,[2]Sheet1!$B:$C,2,FALSE) -> 03.GS401-K5A200Z | C2: ALZWJ43029-包装 | D2: ALZWJ43029-包装 | F2: 件 | G2: ALZWJ43029-前段 | H2: ALZWJ43029-前段 | J2: 件 | K2: 1
A3: ALZWJ43029 | B3: =VLOOKUP(A3,[2]Sheet1!$B:$C,2,FALSE) -> 03.GS401-K5A200Z | C3: ALZWJ43029-前段 | D3: ALZWJ43029-前段 | F3: 件 | G3: 01.GS099-000821Z | H3: 099-0821铝管直管 | I3: Φ16*1.2*220 3003-O | J3: 根 | K3: 1
A4: ALZWJ43028 | B4: =VLOOKUP(A4,[2]Sheet1!$B:$C,2,FALSE) -> 03.GS401-K5A100Z | C4: ALZWJ43028-包装 | D4: ALZWJ43028-包装 | F4: 件 | G4: ALZWJ43028-前段 | H4: ALZWJ43028-前段 | J4: 件 | K4: 1
A5: ALZWJ43028 | B5: =VLOOKUP(A5,[2]Sheet1!$B:$C,2,FALSE) -> 03.GS401-K5A100Z | C5: ALZWJ43028-前段 | D5: ALZWJ43028-前段 | F5: 件 | G5: 01.GS099-000820Z | H5: 099-0820铝管直管 | I5: Φ12*1.2*270 3003-O | J5: 根 | K5: 1
A6: 21410 2HH1C-10 | B6: =VLOOKUP(A6,[2]Sheet1!$B:$C,2,FALSE) -> #N/A | C6: 21410 2HH1C-10-包装 | D6: 21410 2HH1C-10-包装 | F6: 件 | G6: 21410 2HH1C-10-前段 | H6: 21410 2HH1C-10-前段 | J6: 件 | K6: 1
A7: Chiler-100-01-02(SY) | B7: =VLOOKUP(A7,[2]Sheet1!$B:$C,2,FALSE) -> #N/A | C7: Chiler-100-01-02(SY)-包装 | D7: Chiler-100-01-02(SY)-包装 | F7: 件 | G7: Chiler-100-01-02(SY)-前段 | H7: Chiler-100-01-02(SY)-前段 | J7: 件 | K7: 1
A8: Chiller-100-01-02 | B8: =VLOOKUP(A8,[2]Sheet1!$B:$C,2,FALSE) -> 03.GS100-H1A800Z | C8: Chiller-100-01-02-包装 | D8: Chiller-100-01-02-包装 | F8: 件 | G8: Chiller-100-01-02-前段 | H8: Chiller-100-01-02-前段 | J8: 件 | K8: 1
A9: TOC-001-01-01 | B9: =VLOOKUP(A9,[2]Sheet1!$B:$C,2,FALSE) -> 03.GS401-A0A100Z | C9: TOC-001-01-01-包装 | D9: TOC-001-01-01-包装 | F9: 件 | G9: TOC-001-01-01-前段 | H9: TOC-001-01-01-前段 | J9: 件 | K9: 1
A10: BYD01J-105 | B10: =VLOOKUP(A10,[2]Sheet1!$B:$C,2,FALSE) -> 03.GS501-20A700Z | C10: BYD01J-105-包装 | D10: BYD01J-105-包装 | F10: 件 | G10: BYD01J-105-前段 | H10: BYD01J-105-前段 | J10: 件 | K10: 1
A11: BYD01J-104 | B11: =VLOOKUP(A11,[2]Sheet1!$B:$C,2,FALSE) -> 03.GS501-20A600Z | C11: BYD01J-104-包装 | D11: BYD01J-104-包装 | F11: 件 | G11: BYD01J-104-前段 | H11: BYD01J-104-前段 | J11: 件 | K11: 1
A12: 302006462AA-01-06 | B12: =VLOOKUP(A12,[2]Sheet1!$B:$C,2,FALSE) -> 03.GS100-J7A900Z | C12: 302006462AA-01-06-包装 | D12: 302006462AA-01-06-包装 | F12: 件 | G12: 302006462AA-01-06-前段 | H12: 302006462AA-01-06-前段 | J12: 件 | K12: 1
A13: 301006940AA-15 | B13: =VLOOKUP(A13,[2]Sheet1!$B:$C,2,FALSE) -> 03.GS401-L1A200Z | C13: 301006940AA-15-包装 | D13: 301006940AA-15-包装 | F13: 件 | G13: 301006940AA-15-前段 | H13: 301006940AA-15-前段 | J13: 件 | K13: 1
A14: 301006940AA-14 | B14: =VLOOKUP(A14,[2]Sheet1!$B:$C,2,FALSE) -> 03.GS401-L1A100Z | C14: 301006940AA-14-包装 | D14: 301006940AA-14-包装 | F14: 件 | G14: 301006940AA-14-前段 | H14: 301006940AA-14-前段 | J14: 件 | K14: 1
A15: 301003741AA-14 | B15: =VLOOKUP(A15,[2]Sheet1!$B:$C,2,FALSE) -> 03.GS100-I7A600Z | C15: 301003741AA-14-包装 | D15: 301003741AA-14-包装 | F15: 件 | G15: 301003741AA-14-前段 | H15: 301003741AA-14-前段 | J15: 件 | K15: 1
A16: 301004561AA-01-13 | B16: =VLOOKUP(A16,[2]Sheet1!$B:$C,2,FALSE) -> 03.GS100-H1A400Z | C16: 301004561AA-01-13-包装 | D16: 301004561AA-01-13-包装 | F16: 件 | G16: 301004561AA-01-13-前段 | H16: 301004561AA-01-13-前段 | J16: 件 | K16: 1
A17: 21606 2HH0B-05 | B17: =VLOOKUP(A17,[2]Sheet1!$B:$C,2,FALSE) -> 03.GS401-J7A200Z | C17: 21606 2HH0B-05-包装 | D17: 21606 2HH0B-05-包装 | F17: 件 | G17: 21606 2HH0B-05-前段 | H17: 21606 2HH0B-05-前段 | J17: 件 | K17: 1
... A28: 78E03A205 | B28: =VLOOKUP(A28,[2]Sheet1!$B:$C,2,FALSE) -> 03.GS700-A5A300Z | C28: 78E03A205-KD | D28: 78E03A205-KD | F28: 根 | G28: 78E03A205-前段 | H28: 78E03A205-AC高低压管总成-装配前段 | J28: 件 | K28: 1
A29: =VLOOKUP(C29,[1]工艺路线!$A:$E,5,FALSE) -> 78E03A201-KD | B29: =VLOOKUP(A29,[2]Sheet1!$B:$C,2,FALSE) -> 03.GS700-A5A500Z | C29: 78E03A201-KD | D29: 78E03A201-KD | F29: 根 | G29: 78E03A205-组件4-后段 | H29: 78E03A205-组件4-后段 | J29: 件 | K29: 1
A30: =VLOOKUP(C30,[1]工艺路线!$A:$E,5,FALSE) -> 78E03A201-KD | B30: =VLOOKUP(A30,[2]Sheet1!$B:$C,2,FALSE) -> 03.GS700-A5A500Z | C30: 78E03A201-KD | D30: 78E03A201-KD | F30: 根 | G30: 78E03A205-组件3-后段 | H30: 78E03A205-组件3-后段 | J30: 件 | K30: 1
A31: =VLOOKUP(C31,[1]工艺路线!$A:$E,5,FALSE) -> 78E03A201-KD | B31: =VLOOKUP(A31,[2]Sheet1!$B:$C,2,FALSE) -> 03.GS700-A5A500Z | C31: 78E03A201-KD | D31: 78E03A201-KD | F31: 根 | G31: 78E03A205-组件1-后段 | H31: 78E03A205-组件1-后段 | J31: 件 | K31: 1
A32: =VLOOKUP(C32,[1]工艺路线!$A:$E,5,FALSE) -> 78E03A201-KD | B32: =VLOOKUP(A32,[2]Sheet1!$B:$C,2,FALSE) -> 03.GS700-A5A500Z | C32: 78E03A201-KD | D32: 78E03A201-KD | F32: 根 | G32: 78E03A201-组件2-后段 | H32: 78E03A201-组件2-后段 | J32: 件 | K32: 1
A33: 301004574AA | B33: =VLOOKUP(A33,[2]Sheet1!$B:$C,2,FALSE) -> 03.GS700-A5A400Z | C33: 301004574AA | D33: 301004574AA装配后段 | F33: 件 | G33: 301004574AA装配前段 | H33: 301004574AA装配前段 | J33: 件 | K33: 1
A34: 301004574AA | B34: =VLOOKUP(A34,[2]Sheet1!$B:$C,2,FALSE) -> 03.GS700-A5A400Z | C34: 301004574AA装配前段 | D34: 301004574AA装配前段 | F34: 件 | G34: 78E03A205-组件4-后段 | H34: 78E03A205-组件4-后段 | J34: 件 | K34: 1
A35: 301004574AA | B35: =VLOOKUP(A35,[2]Sheet1!$B:$C,2,FALSE) -> 03.GS700-A5A400Z | C35: 301004574AA装配前段 | D35: 301004574AA装配前段 | F35: 件 | G35: 78E03A205-组件3-后段 | H35: 78E03A205-组件3-后段 | J35: 件 | K35: 1
A36: 301004574AA | B36: =VLOOKUP(A36,[2]Sheet1!$B:$C,2,FALSE) -> 03.GS700-A5A400Z | C36: 301004574AA装配前段 | D36: 301004574AA装配前段 | F36: 件 | G36: 78E03A205-组件1-后段 | H36: 78E03A205-组件1-后段 | J36: 件 | K36: 1
A37: 301004574AA | B37: =VLOOKUP(A37,[2]Sheet1!$B:$C,2,FALSE) -> 03.GS700-A5A400Z | C37: 301004574AA装配前段 | D37: 301004574AA装配前段 | F37: 件 | G37: 78E03A201-组件2-后段 | H37: 78E03A201-组件2-后段 | J37: 件 | K37: 1
A38: =VLOOKUP(C38,[1]工艺路线!$A:$E,5,FALSE) -> 301004142AA | B38: =VLOOKUP(A38,[2]Sheet1!$B:$C,2,FALSE) -> 03.GS700-E0A200Z | C38: 301004142AA | D38: 301004142AA-装配 | F38: 件 | G38: 301004142AA-组合件总成2 | H38: 301004142AA-组合件总成2 | J38: 件 | K38: 1
A39: =VLOOKUP(C39,[1]工艺路线!$A:$E,5,FALSE) -> 301004142AA | B39: =VLOOKUP(A39,[2]Sheet1!$B:$C,2,FALSE) -> 03.GS700-E0A200Z | C39: 301004142AA | D39: 301004142AA-装配 | F39: 件 | G39: 301004142AA-组合件总成1 | H39: 301004142AA-组合件总成1 | J39: 件 | K39: 1
A40: =VLOOKUP(C40,[1]工艺路线!$A:$E,5,FALSE) -> 301004142AA | B40: =VLOOKUP(A40,[2]Sheet1!$B:$C,2,FALSE) -> 03.GS700-E0A200Z | C40: 301004142AA | D40: 301004142AA-装配 | F40: 件 | G40: 01.GS016-000275Z | H40: 016-0275管夹3 | J40: 个 | K40: 1
A41: =VLOOKUP(C41,[1]工艺路线!$A:$E,5,FALSE) -> 301004142AA | B41: =VLOOKUP(A41,[2]Sheet1!$B:$C,2,FALSE) -> 03.GS700-E0A200Z | C41: 301004142AA | D41: 301004142AA-装配 | F41: 件 | G41: 01.GS016-000274Z | H41: 016-0274管夹2 | J41: 个 | K41: 1
A42: =VLOOKUP(C42,[1]工艺路线!$A:$E,5,FALSE) -> 301004142AA | B42: =VLOOKUP(A42,[2]Sheet1!$B:$C,2,FALSE) -> 03.GS700-E0A200Z | C42: 301004142AA | D42: 301004142AA-装配 | F42: 件 | G42: 01.GS016-000237Z | H42: 016-0237管夹 | I42: SPCC（电渡+电泳）无螺母 | J42: 个 | K42: 1
A43: =VLOOKUP(C43,[1]工艺路线!$A:$E,5,FALSE) -> 301004142AA | B43: =VLOOKUP(A43,[2]Sheet1!$B:$C,2,FALSE) -> 03.GS700-E0A200Z | C43: 301004142AA | D43: 301004142AA-装配 | F43: 件 | G43: 01.GS016-000216Z | H43: 016-0216管夹 | I43: SPCC（电渡+电泳） 有螺母 | J43: 个 | K43: 1
A44: =VLOOKUP(C44,[1]工艺路线!$A:$E,5,FALSE) -> 301004142AA | B44: =VLOOKUP(A44,[2]Sheet1!$B:$C,2,FALSE) -> 03.GS700-E0A200Z | C44: 301004142AA | D44: 301004142AA-装配 | F44: 件 | G44: 01.GS015-000025Z | H44: 015-0025橡胶垫 | I44: EPDM | J44: 个 | K44: 2
A45: =VLOOKUP(C45,[1]工艺路线!$A:$E,5,FALSE) -> 301004142AA | B45: =VLOOKUP(A45,[2]Sheet1!$B:$C,2,FALSE) -> 03.GS700-E0A200Z | C45: 301004142AA | D45: 301004142AA-装配 | F45: 件 | G45: 01.GS015-000022Z | H45: 015-0022橡胶衬套 | I45: φ10*25 EDPM | J45: 个 | K45: 3
A46: =VLOOKUP(C46,[1]工艺路线!$A:$E,5,FALSE) -> 301004142AA | B46: =VLOOKUP(A46,[2]Sheet1!$B:$C,2,FALSE) -> 03.GS700-E0A200Z | C46: 301004142AA | D46: 301004142AA-装配 | F46: 件 | G46: 01.GS015-000021Z | H46: 015-0021橡胶衬套 | I46: φ19*25A EPDM | J46: 个 | K46: 3
A47: =VLOOKUP(C47,[1]工艺路线!$A:$E,5,FALSE) -> 301004142AA | B47: =VLOOKUP(A47,[2]Sheet1!$B:$C,2,FALSE) -> 03.GS700-E0A200Z | C47: 301004142AA | D47: 301004142AA-装配 | F47: 件 | G47: 01.GS013-000005Z | H47: 013-0005衬套 | I47: SPCC | J47: 个 | K47: 2
A48: =VLOOKUP(C48,[1]工艺路线!$A:$E,5,FALSE) -> 301004142AA | B48: =VLOOKUP(A48,[2]Sheet1!$B:$C,2,FALSE) -> 03.GS700-E0A200Z | C48: 301004142AA | D48: 301004142AA-装配 | F48: 件 | G48: 01.GS010-000081Z | H48: 010-0081堵帽 | I48: >PVC< Φ9 | J48: 个 | K48: 1
A49: =VLOOKUP(C49,[1]工艺路线!$A:$E,5,FALSE) -> 301004142AA | B49: =VLOOKUP(A49,[2]Sheet1!$B:$C,2,FALSE) -> 03.GS700-E0A200Z | C49: 301004142AA | D49: 301004142AA-装配 | F49: 件 | G49: 01.GS010-000080Z | H49: 010-0080堵帽 | I49: >PVC< Φ18.2 | J49: 个 | K49: 1
A50: =VLOOKUP(C50,[1]工艺路线!$A:$E,5,FALSE) -> 301004142AA | B50: =VLOOKUP(A50,[2]Sheet1!$B:$C,2,FALSE) -> 03.GS700-E0A200Z | C50: 301004142AA | D50: 301004142AA-装配 | F50: 件 | G50: 01.GS010-000078Z | H50: 010-0078堵帽 | J50: 个 | K50: 1
...
